<?xml version="1.0"?>
<robot name="Pendulum"
    xmlns="https://drake.mit.edu"
    xmlns:xsi="http://www.w3.org/2001/XMLSchema-instance"
    xsi:schemaLocation="https://drake.mit.edu ../../doc/drakeURDF.xsd">
<material name="green">
	<color rgba=".3 .6 .4 1"/>
</material>
<material name="red">
	<color rgba=".9 .1 0 1"/>
</material>
<material name="blue">
	<color rgba="0 0 0.7 1.0"/>
</material>

<link name="base">
	<inertial>
		<origin rpy="0 0 0" xyz="0 0 0"/>
		<mass value="1"/>
		<inertia ixx="0" ixy="0" ixz="0" iyy="0" iyz="0" izz="0"/>
	</inertial>
	<visual>
		<origin xyz="0 0 0"/>
		<geometry>
			<sphere radius=".025"/>
		</geometry>
		<material name="green"/>
	</visual>
</link>

<link name="link_1">
	<inertial>
		<origin rpy="0 0 0" xyz="0 0 -0.3"/>
		<mass value="0.3"/>
		<inertia ixx="0" ixy="0" ixz="0" iyy="0" iyz="0" izz="0"/>
	</inertial>
	<visual>
		<origin rpy="0 0 0" xyz="0 0 -.15"/>
		<geometry>
			<cylinder length="0.3" radius="0.015"/>
		</geometry>
		<material name="red"/>
	</visual>
	<visual>
		<origin xyz="0 0 -0.3"/>
		<geometry>
			<sphere radius=".025"/>
		</geometry>
		<material name="blue"/>
	</visual>
</link>

<joint name="joint1" type="continuous">
	<parent link="base"/>
	<child link="link_1"/>
	<axis xyz="0 1 0"/>
	<dynamics damping="0.0" friction="0.0"/>
</joint>

<transmission name="joint1_transmission" type="SimpleTransmission">
	<actuator name="tau"/>
	<joint name="joint1"/>
	<mechanicalReduction>1</mechanicalReduction>
</transmission>
</robot>
